{"name": "test_user_login", "status": "failed", "statusDetails": {"message": "Failed: Error evaluating 'xfail' condition\n    expected failure as name is dynamic\n              ^\nSyntaxError: invalid syntax", "trace": "invalid syntax (<xfail condition>, line 1)\n\nDuring handling of the above exception, another exception occurred:\nError evaluating 'xfail' condition\n    expected failure as name is dynamic\n              ^\nSyntaxError: invalid syntax"}, "start": 1726058664756, "stop": 1726058664756, "uuid": "fe8506df-7928-4e89-a667-0282d0fc91aa", "historyId": "0bbebac222397b93d463e6822fa79e9c", "testCaseId": "0bbebac222397b93d463e6822fa79e9c", "fullName": "tests.test_login#test_user_login", "labels": [{"name": "tag", "value": "@pytest.mark.xfail('expected failure as name is dynamic')"}, {"name": "parentSuite", "value": "tests"}, {"name": "suite", "value": "test_login"}, {"name": "host", "value": "Holy-Fuck"}, {"name": "thread", "value": "7196-MainThread"}, {"name": "framework", "value": "pytest"}, {"name": "language", "value": "cpython3"}, {"name": "package", "value": "tests.test_login"}]}